telegram.error.Conflict: Conflict: terminated by other getUpdates request; make sure that only one bot instance is running
    ^
  File "/opt/render/project/src/.venv/lib/python3.13/site-packages/telegram/_bot.py", line 703, in _post
    return await self._do_post(
           ^^^^^^^^^^^^^^^^^^^^
    ...<6 lines>...
    )
    ^
  File "/opt/render/project/src/.venv/lib/python3.13/site-packages/telegram/ext/_extbot.py", line 372, in _do_post
    return await super()._do_post(
           ^^^^^^^^^^^^^^^^^^^^^^^
    ...<6 lines>...
    )
    ^
  File "/opt/render/project/src/.venv/lib/python3.13/site-packages/telegram/_bot.py", line 732, in _do_post
    result = await request.post(
             ^^^^^^^^^^^^^^^^^^^
    ...<6 lines>...
    )
    ^
  File "/opt/render/project/src/.venv/lib/python3.13/site-packages/telegram/request/_baserequest.py", line 198, in post
    result = await self._request_wrapper(
             ^^^^^^^^^^^^^^^^^^^^^^^^^^^^
    ...<7 lines>...
    )
    ^
  File "/opt/render/project/src/.venv/lib/python3.13/site-packages/telegram/request/_baserequest.py", line 375, in _request_wrapper
    raise exception
telegram.error.Conflict: Conflict: terminated by other getUpdates request; make sure that only one bot instance is running
2025-09-15 20:43:48,264 - __main__ - ERROR - Update None caused error Conflict: terminated by other getUpdates request; make sure that only one bot instance is running
Traceback (most recent call last):
  File "/opt/render/project/src/.venv/lib/python3.13/site-packages/telegram/ext/_utils/networkloop.py", line 122, in network_retry_loop
    await do_action()
  File "/opt/render/project/src/.venv/lib/python3.13/site-packages/telegram/ext/_utils/networkloop.py", line 115, in do_action
    action_cb_task.result()
    ~~~~~~~~~~~~~~~~~~~~~^^
  File "/opt/render/project/src/.venv/lib/python3.13/site-packages/telegram/ext/_updater.py", line 340, in polling_action_cb
    updates = await self.bot.get_updates(
              ^^^^^^^^^^^^^^^^^^^^^^^^^^^
    ...<3 lines>...
    )
    ^
  File "/opt/render/project/src/.venv/lib/python3.13/site-packages/telegram/ext/_extbot.py", line 676, in get_updates
    updates = await super().get_updates(
              ^^^^^^^^^^^^^^^^^^^^^^^^^^
    ...<9 lines>...
    )
    ^
  File "/opt/render/project/src/.venv/lib/python3.13/site-packages/telegram/_bot.py", line 4780, in get_updates
    await self._post(
    ^^^^^^^^^^^^^^^^^
    ...<7 lines>...
    ),
    ^
  File "/opt/render/project/src/.venv/lib/python3.13/site-packages/telegram/_bot.py", line 703, in _post
    return await self._do_post(
           ^^^^^^^^^^^^^^^^^^^^
    ...<6 lines>...
    )
    ^
  File "/opt/render/project/src/.venv/lib/python3.13/site-packages/telegram/ext/_extbot.py", line 372, in _do_post
    return await super()._do_post(
           ^^^^^^^^^^^^^^^^^^^^^^^
    ...<6 lines>...
    )
    ^
  File "/opt/render/project/src/.venv/lib/python3.13/site-packages/telegram/_bot.py", line 732, in _do_post
    result = await request.post(
             ^^^^^^^^^^^^^^^^^^^
    ...<6 lines>...
    )
    ^
  File "/opt/render/project/src/.venv/lib/python3.13/site-packages/telegram/request/_baserequest.py", line 198, in post
    result = await self._request_wrapper(
             ^^^^^^^^^^^^^^^^^^^^^^^^^^^^
    ...<7 lines>...
    )
    ^
  File "/opt/render/project/src/.venv/lib/python3.13/site-packages/telegram/request/_baserequest.py", line 375, in _request_wrapper
    raise exception
telegram.error.Conflict: Conflict: terminated by other getUpdates request; make sure that only one bot instance is running
2025-09-15 20:44:18,145 - __main__ - ERROR - Update None caused error Conflict: terminated by other getUpdates request; make sure that only one bot instance is running
Traceback (most recent call last):
  File "/opt/render/project/src/.venv/lib/python3.13/site-packages/telegram/ext/_utils/networkloop.py", line 122, in network_retry_loop
    await do_action()
  File "/opt/render/project/src/.venv/lib/python3.13/site-packages/telegram/ext/_utils/networkloop.py", line 115, in do_action
    action_cb_task.result()
    ~~~~~~~~~~~~~~~~~~~~~^^
  File "/opt/render/project/src/.venv/lib/python3.13/site-packages/telegram/ext/_updater.py", line 340, in polling_action_cb
    updates = await self.bot.get_updates(
              ^^^^^^^^^^^^^^^^^^^^^^^^^^^
    ...<3 lines>...
    )
    ^
  File "/opt/render/project/src/.venv/lib/python3.13/site-packages/telegram/ext/_extbot.py", line 676, in get_updates
    updates = await super().get_updates(
              ^^^^^^^^^^^^^^^^^^^^^^^^^^
    ...<9 lines>...
    )
    ^
  File "/opt/render/project/src/.venv/lib/python3.13/site-packages/telegram/_bot.py", line 4780, in get_updates
    await self._post(
    ^^^^^^^^^^^^^^^^^
    ...<7 lines>...
    ),
    ^
  File "/opt/render/project/src/.venv/lib/python3.13/site-packages/telegram/_bot.py", line 703, in _post
    return await self._do_post(
           ^^^^^^^^^^^^^^^^^^^^
    ...<6 lines>...
    )
    ^
  File "/opt/render/project/src/.venv/lib/python3.13/site-packages/telegram/ext/_extbot.py", line 372, in _do_post
    return await super()._do_post(
           ^^^^^^^^^^^^^^^^^^^^^^^
    ...<6 lines>...
    )
    ^
  File "/opt/render/project/src/.venv/lib/python3.13/site-packages/telegram/_bot.py", line 732, in _do_post
    result = await request.post(
             ^^^^^^^^^^^^^^^^^^^
    ...<6 lines>...
    )
    ^
  File "/opt/render/project/src/.venv/lib/python3.13/site-packages/telegram/request/_baserequest.py", line 198, in post
    result = await self._request_wrapper(
             ^^^^^^^^^^^^^^^^^^^^^^^^^^^^
    ...<7 lines>...
    )
    ^
  File "/opt/render/project/src/.venv/lib/python3.13/site-packages/telegram/request/_baserequest.py", line 375, in _request_wrapper
    raise exception
telegram.error.Conflict: Conflict: terminated by other getUpdates request; make sure that only one bot instance is running
2025-09-15 20:44:52,404 - __main__ - ERROR - Update None caused error Conflict: terminated by other getUpdates request; make sure that only one bot instance is running
Traceback (most recent call last):
  File "/opt/render/project/src/.venv/lib/python3.13/site-packages/telegram/ext/_utils/networkloop.py", line 122, in network_retry_loop
    await do_action()
  File "/opt/render/project/src/.venv/lib/python3.13/site-packages/telegram/ext/_utils/networkloop.py", line 115, in do_action
    action_cb_task.result()
    ~~~~~~~~~~~~~~~~~~~~~^^
  File "/opt/render/project/src/.venv/lib/python3.13/site-packages/telegram/ext/_updater.py", line 340, in polling_action_cb
    updates = await self.bot.get_updates(
              ^^^^^^^^^^^^^^^^^^^^^^^^^^^
    ...<3 lines>...
    )
    ^
  File "/opt/render/project/src/.venv/lib/python3.13/site-packages/telegram/ext/_extbot.py", line 676, in get_updates
    updates = await super().get_updates(
              ^^^^^^^^^^^^^^^^^^^^^^^^^^
    ...<9 lines>...
    )
    ^
  File "/opt/render/project/src/.venv/lib/python3.13/site-packages/telegram/_bot.py", line 4780, in get_updates
    await self._post(
    ^^^^^^^^^^^^^^^^^
    ...<7 lines>...
    ),
    ^
  File "/opt/render/project/src/.venv/lib/python3.13/site-packages/telegram/_bot.py", line 703, in _post
    return await self._do_post(
           ^^^^^^^^^^^^^^^^^^^^
    ...<6 lines>...
    )
    ^
  File "/opt/render/project/src/.venv/lib/python3.13/site-packages/telegram/ext/_extbot.py", line 372, in _do_post
    return await super()._do_post(
           ^^^^^^^^^^^^^^^^^^^^^^^
    ...<6 lines>...
    )
    ^
  File "/opt/render/project/src/.venv/lib/python3.13/site-packages/telegram/_bot.py", line 732, in _do_post
    result = await request.post(
             ^^^^^^^^^^^^^^^^^^^
    ...<6 lines>...
    )
    ^
  File "/opt/render/project/src/.venv/lib/python3.13/site-packages/telegram/request/_baserequest.py", line 198, in post
    result = await self._request_wrapper(
             ^^^^^^^^^^^^^^^^^^^^^^^^^^^^
    ...<7 lines>...
    )
    ^
  File "/opt/render/project/src/.venv/lib/python3.13/site-packages/telegram/request/_baserequest.py", line 375, in _request_wrapper
    raise exception
telegram.error.Conflict: Conflict: terminated by other getUpdates request; make sure that only one bot instance is running
2025-09-15 20:45:26,661 - __main__ - ERROR - Update None caused error Conflict: terminated by other getUpdates request; make sure that only one bot instance is running
Traceback (most recent call last):
  File "/opt/render/project/src/.venv/lib/python3.13/site-packages/telegram/ext/_utils/networkloop.py", line 122, in network_retry_loop
    await do_action()
  File "/opt/render/project/src/.venv/lib/python3.13/site-packages/telegram/ext/_utils/networkloop.py", line 115, in do_action
    action_cb_task.result()
    ~~~~~~~~~~~~~~~~~~~~~^^
  File "/opt/render/project/src/.venv/lib/python3.13/site-packages/telegram/ext/_updater.py", line 340, in polling_action_cb
    updates = await self.bot.get_updates(
              ^^^^^^^^^^^^^^^^^^^^^^^^^^^
    ...<3 lines>...
    )
    ^
  File "/opt/render/project/src/.venv/lib/python3.13/site-packages/telegram/ext/_extbot.py", line 676, in get_updates
    updates = await super().get_updates(
              ^^^^^^^^^^^^^^^^^^^^^^^^^^
    ...<9 lines>...
    )
    ^
  File "/opt/render/project/src/.venv/lib/python3.13/site-packages/telegram/_bot.py", line 4780, in get_updates
    await self._post(
    ^^^^^^^^^^^^^^^^^
    ...<7 lines>...
    ),
    ^
  File "/opt/render/project/src/.venv/lib/python3.13/site-packages/telegram/_bot.py", line 703, in _post
    return await self._do_post(
           ^^^^^^^^^^^^^^^^^^^^
    ...<6 lines>...
    )
    ^
  File "/opt/render/project/src/.venv/lib/python3.13/site-packages/telegram/ext/_extbot.py", line 372, in _do_post
    return await super()._do_post(
           ^^^^^^^^^^^^^^^^^^^^^^^
    ...<6 lines>...
    )
    ^
  File "/opt/render/project/src/.venv/lib/python3.13/site-packages/telegram/_bot.py", line 732, in _do_post
    result = await request.post(
             ^^^^^^^^^^^^^^^^^^^
    ...<6 lines>...
    )
    ^
  File "/opt/render/project/src/.venv/lib/python3.13/site-packages/telegram/request/_baserequest.py", line 198, in post
    result = await self._request_wrapper(
             ^^^^^^^^^^^^^^^^^^^^^^^^^^^^
    ...<7 lines>...
    )
    ^
  File "/opt/render/project/src/.venv/lib/python3.13/site-packages/telegram/request/_baserequest.py", line 375, in _request_wrapper
    raise exception
telegram.error.Conflict: Conflict: terminated by other getUpdates request; make sure that only one bot instance is running
2025-09-15 20:46:00,927 - __main__ - ERROR - Update None caused error Conflict: terminated by other getUpdates request; make sure that only one bot instance is running
Traceback (most recent call last):
  File "/opt/render/project/src/.venv/lib/python3.13/site-packages/telegram/ext/_utils/networkloop.py", line 122, in network_retry_loop
    await do_action()
  File "/opt/render/project/src/.venv/lib/python3.13/site-packages/telegram/ext/_utils/networkloop.py", line 115, in do_action
    action_cb_task.result()
    ~~~~~~~~~~~~~~~~~~~~~^^
  File "/opt/render/project/src/.venv/lib/python3.13/site-packages/telegram/ext/_updater.py", line 340, in polling_action_cb
    updates = await self.bot.get_updates(
              ^^^^^^^^^^^^^^^^^^^^^^^^^^^
    ...<3 lines>...
    )
    ^
  File "/opt/render/project/src/.venv/lib/python3.13/site-packages/telegram/ext/_extbot.py", line 676, in get_updates
    updates = await super().get_updates(
              ^^^^^^^^^^^^^^^^^^^^^^^^^^
    ...<9 lines>...
    )
    ^
  File "/opt/render/project/src/.venv/lib/python3.13/site-packages/telegram/_bot.py", line 4780, in get_updates
    await self._post(
    ^^^^^^^^^^^^^^^^^
    ...<7 lines>...
    ),
    ^
  File "/opt/render/project/src/.venv/lib/python3.13/site-packages/telegram/_bot.py", line 703, in _post
    return await self._do_post(
           ^^^^^^^^^^^^^^^^^^^^
    ...<6 lines>...
    )
    ^
  File "/opt/render/project/src/.venv/lib/python3.13/site-packages/telegram/ext/_extbot.py", line 372, in _do_post
    return await super()._do_post(
           ^^^^^^^^^^^^^^^^^^^^^^^
    ...<6 lines>...
    )
    ^
  File "/opt/render/project/src/.venv/lib/python3.13/site-packages/telegram/_bot.py", line 732, in _do_post
    result = await request.post(
             ^^^^^^^^^^^^^^^^^^^
    ...<6 lines>...
    )
    ^
  File "/opt/render/project/src/.venv/lib/python3.13/site-packages/telegram/request/_baserequest.py", line 198, in post
    result = await self._request_wrapper(
             ^^^^^^^^^^^^^^^^^^^^^^^^^^^^
    ...<7 lines>...
    )
    ^
  File "/opt/render/project/src/.venv/lib/python3.13/site-packages/telegram/request/_baserequest.py", line 375, in _request_wrapper
    raise exception
telegram.error.Conflict: Conflict: terminated by other getUpdates request; make sure that only one bot instance is running
2025-09-15 20:46:35,144 - __main__ - ERROR - Update None caused error Conflict: terminated by other getUpdates request; make sure that only one bot instance is running
Traceback (most recent call last):
  File "/opt/render/project/src/.venv/lib/python3.13/site-packages/telegram/ext/_utils/networkloop.py", line 122, in network_retry_loop
    await do_action()
  File "/opt/render/project/src/.venv/lib/python3.13/site-packages/telegram/ext/_utils/networkloop.py", line 115, in do_action
    action_cb_task.result()
    ~~~~~~~~~~~~~~~~~~~~~^^
  File "/opt/render/project/src/.venv/lib/python3.13/site-packages/telegram/ext/_updater.py", line 340, in polling_action_cb
    updates = await self.bot.get_updates(
              ^^^^^^^^^^^^^^^^^^^^^^^^^^^
    ...<3 lines>...
    )
    ^
  File "/opt/render/project/src/.venv/lib/python3.13/site-packages/telegram/ext/_extbot.py", line 676, in get_updates
    updates = await super().get_updates(
              ^^^^^^^^^^^^^^^^^^^^^^^^^^
    ...<9 lines>...
    )
    ^
  File "/opt/render/project/src/.venv/lib/python3.13/site-packages/telegram/_bot.py", line 4780, in get_updates
    await self._post(
    ^^^^^^^^^^^^^^^^^
    ...<7 lines>...
    ),
    ^
  File "/opt/render/project/src/.venv/lib/python3.13/site-packages/telegram/_bot.py", line 703, in _post
    return await self._do_post(
           ^^^^^^^^^^^^^^^^^^^^
    ...<6 lines>...
    )
    ^
  File "/opt/render/project/src/.venv/lib/python3.13/site-packages/telegram/ext/_extbot.py", line 372, in _do_post
    return await super()._do_post(
           ^^^^^^^^^^^^^^^^^^^^^^^
    ...<6 lines>...
    )
    ^
  File "/opt/render/project/src/.venv/lib/python3.13/site-packages/telegram/_bot.py", line 732, in _do_post
    result = await request.post(
             ^^^^^^^^^^^^^^^^^^^
    ...<6 lines>...
    )
    ^
  File "/opt/render/project/src/.venv/lib/python3.13/site-packages/telegram/request/_baserequest.py", line 198, in post
    result = await self._request_wrapper(
             ^^^^^^^^^^^^^^^^^^^^^^^^^^^^
    ...<7 lines>...
    )
    ^
  File "/opt/render/project/src/.venv/lib/python3.13/site-packages/telegram/request/_baserequest.py", line 375, in _request_wrapper
    raise exception
telegram.error.Conflict: Conflict: terminated by other getUpdates request; make sure that only one bot instance is running
2025-09-15 20:47:08,729 - __main__ - ERROR - Update None caused error Conflict: terminated by other getUpdates request; make sure that only one bot instance is running
Traceback (most recent call last):
  File "/opt/render/project/src/.venv/lib/python3.13/site-packages/telegram/ext/_utils/networkloop.py", line 122, in network_retry_loop
    await do_action()
  File "/opt/render/project/src/.venv/lib/python3.13/site-packages/telegram/ext/_utils/networkloop.py", line 115, in do_action
    action_cb_task.result()
    ~~~~~~~~~~~~~~~~~~~~~^^
  File "/opt/render/project/src/.venv/lib/python3.13/site-packages/telegram/ext/_updater.py", line 340, in polling_action_cb
    updates = await self.bot.get_updates(
              ^^^^^^^^^^^^^^^^^^^^^^^^^^^
    ...<3 lines>...
    )
    ^
  File "/opt/render/project/src/.venv/lib/python3.13/site-packages/telegram/ext/_extbot.py", line 676, in get_updates
    updates = await super().get_updates(
              ^^^^^^^^^^^^^^^^^^^^^^^^^^
    ...<9 lines>...
    )
    ^
  File "/opt/render/project/src/.venv/lib/python3.13/site-packages/telegram/_bot.py", line 4780, in get_updates
    await self._post(
    ^^^^^^^^^^^^^^^^^
    ...<7 lines>...
    ),
    ^
  File "/opt/render/project/src/.venv/lib/python3.13/site-packages/telegram/_bot.py", line 703, in _post
    return await self._do_post(
           ^^^^^^^^^^^^^^^^^^^^
    ...<6 lines>...
    )
    ^
  File "/opt/render/project/src/.venv/lib/python3.13/site-packages/telegram/ext/_extbot.py", line 372, in _do_post
    return await super()._do_post(
           ^^^^^^^^^^^^^^^^^^^^^^^
    ...<6 lines>...
    )
    ^
  File "/opt/render/project/src/.venv/lib/python3.13/site-packages/telegram/_bot.py", line 732, in _do_post
    result = await request.post(
             ^^^^^^^^^^^^^^^^^^^
    ...<6 lines>...
    )
    ^
  File "/opt/render/project/src/.venv/lib/python3.13/site-packages/telegram/request/_baserequest.py", line 198, in post
    result = await self._request_wrapper(
             ^^^^^^^^^^^^^^^^^^^^^^^^^^^^
    ...<7 lines>...
    )
    ^
  File "/opt/render/project/src/.venv/lib/python3.13/site-packages/telegram/request/_baserequest.py", line 375, in _request_wrapper
    raise exception
telegram.error.Conflict: Conflict: terminated by other getUpdates request; make sure that only one bot instance is running
2025-09-15 20:47:46,961 - __main__ - ERROR - Update None caused error Conflict: terminated by other getUpdates request; make sure that only one bot instance is running
Traceback (most recent call last):
  File "/opt/render/project/src/.venv/lib/python3.13/site-packages/telegram/ext/_utils/networkloop.py", line 122, in network_retry_loop
    await do_action()
  File "/opt/render/project/src/.venv/lib/python3.13/site-packages/telegram/ext/_utils/networkloop.py", line 115, in do_action
    action_cb_task.result()
    ~~~~~~~~~~~~~~~~~~~~~^^
  File "/opt/render/project/src/.venv/lib/python3.13/site-packages/telegram/ext/_updater.py", line 340, in polling_action_cb
    updates = await self.bot.get_updates(
              ^^^^^^^^^^^^^^^^^^^^^^^^^^^
    ...<3 lines>...
    )
    ^
  File "/opt/render/project/src/.venv/lib/python3.13/site-packages/telegram/ext/_extbot.py", line 676, in get_updates
    updates = await super().get_updates(
              ^^^^^^^^^^^^^^^^^^^^^^^^^^
    ...<9 lines>...
    )
    ^
  File "/opt/render/project/src/.venv/lib/python3.13/site-packages/telegram/_bot.py", line 4780, in get_updates
    await self._post(
    ^^^^^^^^^^^^^^^^^
    ...<7 lines>...
    ),
    ^
  File "/opt/render/project/src/.venv/lib/python3.13/site-packages/telegram/_bot.py", line 703, in _post
    return await self._do_post(
           ^^^^^^^^^^^^^^^^^^^^
    ...<6 lines>...
    )
    ^
  File "/opt/render/project/src/.venv/lib/python3.13/site-packages/telegram/ext/_extbot.py", line 372, in _do_post
    return await super()._do_post(
           ^^^^^^^^^^^^^^^^^^^^^^^
    ...<6 lines>...
    )
    ^
  File "/opt/render/project/src/.venv/lib/python3.13/site-packages/telegram/_bot.py", line 732, in _do_post
    result = await request.post(
             ^^^^^^^^^^^^^^^^^^^
    ...<6 lines>...
    )
    ^
  File "/opt/render/project/src/.venv/lib/python3.13/site-packages/telegram/request/_baserequest.py", line 198, in post
    result = await self._request_wrapper(
             ^^^^^^^^^^^^^^^^^^^^^^^^^^^^
    ...<7 lines>...
    )
    ^
  File "/opt/render/project/src/.venv/lib/python3.13/site-packages/telegram/request/_baserequest.py", line 375, in _request_wrapper
    raise exception
telegram.error.Conflict: Conflict: terminated by other getUpdates request; make sure that only one bot instance is running
==> Timed out: Port scan timeout reached, no open ports detected. Bind your service to at least one port. If you don't need to receive traffic on any port, create a background worker instead.
==> Common ways to troubleshoot your deploy: https://render.com/docs/troubleshooting-deploys
2025-09-15 20:48:21,240 - __main__ - ERROR - Update None caused error Conflict: terminated by other getUpdates request; make sure that only one bot instance is running
Traceback (most recent call last):
  File "/opt/render/project/src/.venv/lib/python3.13/site-packages/telegram/ext/_utils/networkloop.py", line 122, in network_retry_loop
    await do_action()
  File "/opt/render/project/src/.venv/lib/python3.13/site-packages/telegram/ext/_utils/networkloop.py", line 115, in do_action
    action_cb_task.result()
    ~~~~~~~~~~~~~~~~~~~~~^^
  File "/opt/render/project/src/.venv/lib/python3.13/site-packages/telegram/ext/_updater.py", line 340, in polling_action_cb
    updates = await self.bot.get_updates(
              ^^^^^^^^^^^^^^^^^^^^^^^^^^^
    ...<3 lines>...
    )
    ^
  File "/opt/render/project/src/.venv/lib/python3.13/site-packages/telegram/ext/_extbot.py", line 676, in get_updates
    updates = await super().get_updates(
              ^^^^^^^^^^^^^^^^^^^^^^^^^^
    ...<9 lines>...
    )
    ^
  File "/opt/render/project/src/.venv/lib/python3.13/site-packages/telegram/_bot.py", line 4780, in get_updates
    await self._post(
    ^^^^^^^^^^^^^^^^^
    ...<7 lines>...
    ),
    ^
  File "/opt/render/project/src/.venv/lib/python3.13/site-packages/telegram/_bot.py", line 703, in _post
    return await self._do_post(
           ^^^^^^^^^^^^^^^^^^^^
    ...<6 lines>...
    )
    ^
  File "/opt/render/project/src/.venv/lib/python3.13/site-packages/telegram/ext/_extbot.py", line 372, in _do_post
    return await super()._do_post(
           ^^^^^^^^^^^^^^^^^^^^^^^
    ...<6 lines>...
    )
    ^
  File "/opt/render/project/src/.venv/lib/python3.13/site-packages/telegram/_bot.py", line 732, in _do_post
    result = await request.post(
             ^^^^^^^^^^^^^^^^^^^
    ...<6 lines>...
    )
    ^
  File "/opt/render/project/src/.venv/lib/python3.13/site-packages/telegram/request/_baserequest.py", line 198, in post
    result = await self._request_wrapper(
             ^^^^^^^^^^^^^^^^^^^^^^^^^^^^
    ...<7 lines>...
    )
    ^
  File "/opt/render/project/src/.venv/lib/python3.13/site-packages/telegram/request/_baserequest.py", line 375, in _request_wrapper
    raise exception
telegram.error.Conflict: Conflict: terminated by other getUpdates request; make sure that only one bot instance is running
2025-09-15 20:48:55,496 - __main__ - ERROR - Update None caused error Conflict: terminated by other getUpdates request; make sure that only one bot instance is running
Traceback (most recent call last):
  File "/opt/render/project/src/.venv/lib/python3.13/site-packages/telegram/ext/_utils/networkloop.py", line 122, in network_retry_loop
    await do_action()
  File "/opt/render/project/src/.venv/lib/python3.13/site-packages/telegram/ext/_utils/networkloop.py", line 115, in do_action
    action_cb_task.result()
    ~~~~~~~~~~~~~~~~~~~~~^^
  File "/opt/render/project/src/.venv/lib/python3.13/site-packages/telegram/ext/_updater.py", line 340, in polling_action_cb
    updates = await self.bot.get_updates(
              ^^^^^^^^^^^^^^^^^^^^^^^^^^^
    ...<3 lines>...
    )
    ^
  File "/opt/render/project/src/.venv/lib/python3.13/site-packages/telegram/ext/_extbot.py", line 676, in get_updates
    updates = await super().get_updates(
              ^^^^^^^^^^^^^^^^^^^^^^^^^^
    ...<9 lines>...
    )
    ^
  File "/opt/render/project/src/.venv/lib/python3.13/site-packages/telegram/_bot.py", line 4780, in get_updates
    await self._post(
    ^^^^^^^^^^^^^^^^^
    ...<7 lines>...
    ),
    ^
  File "/opt/render/project/src/.venv/lib/python3.13/site-packages/telegram/_bot.py", line 703, in _post
    return await self._do_post(
           ^^^^^^^^^^^^^^^^^^^^
    ...<6 lines>...
    )
    ^
  File "/opt/render/project/src/.venv/lib/python3.13/site-packages/telegram/ext/_extbot.py", line 372, in _do_post
    return await super()._do_post(
           ^^^^^^^^^^^^^^^^^^^^^^^
    ...<6 lines>...
    )
    ^
  File "/opt/render/project/src/.venv/lib/python3.13/site-packages/telegram/_bot.py", line 732, in _do_post
    result = await request.post(
             ^^^^^^^^^^^^^^^^^^^
    ...<6 lines>...
    )
    ^
  File "/opt/render/project/src/.venv/lib/python3.13/site-packages/telegram/request/_baserequest.py", line 198, in post
    result = await self._request_wrapper(
             ^^^^^^^^^^^^^^^^^^^^^^^^^^^^
    ...<7 lines>...
    )
    ^
  File "/opt/render/project/src/.venv/lib/python3.13/site-packages/telegram/request/_baserequest.py", line 375, in _request_wrapper
    raise exception
telegram.error.Conflict: Conflict: terminated by other getUpdates request; make sure that only one bot instance is running